Traceback (most recent call last):
  File "test.py", line 7, in <module>
    raise Exception, 'this error will be logged' 
Exception: this error will be logged
